{
 "cells": [
  {
   "cell_type": "code",
   "execution_count": 2,
   "id": "69ecfa83",
   "metadata": {},
   "outputs": [],
   "source": [
    "import tensorflow as tf\n",
    "import numpy as np"
   ]
  },
  {
   "cell_type": "code",
   "execution_count": 3,
   "id": "6e4594a8",
   "metadata": {},
   "outputs": [],
   "source": [
    "base_dir=r\"E:\\PYTHON\\Flower kath golap\""
   ]
  },
  {
   "cell_type": "code",
   "execution_count": 5,
   "id": "eaf3366e",
   "metadata": {},
   "outputs": [
    {
     "name": "stdout",
     "output_type": "stream",
     "text": [
      "Unexpected exception formatting exception. Falling back to standard exception\n"
     ]
    },
    {
     "name": "stderr",
     "output_type": "stream",
     "text": [
      "Traceback (most recent call last):\n",
      "  File \"C:\\Users\\hp\\anaconda3\\envs\\tensorflow\\lib\\site-packages\\IPython\\core\\interactiveshell.py\", line 3398, in run_code\n",
      "    exec(code_obj, self.user_global_ns, self.user_ns)\n",
      "  File \"C:\\Users\\hp\\AppData\\Local\\Temp\\ipykernel_13080\\3530331095.py\", line 17, in <cell line: 17>\n",
      "    train_datagen=train_datagen.flow_from_directory(\n",
      "  File \"C:\\Users\\hp\\anaconda3\\envs\\tensorflow\\lib\\site-packages\\keras\\preprocessing\\image.py\", line 976, in flow_from_directory\n",
      "  File \"C:\\Users\\hp\\anaconda3\\envs\\tensorflow\\lib\\site-packages\\keras_preprocessing\\image\\directory_iterator.py\", line 69, in __new__\n",
      "    from tensorflow.keras.utils import Sequence as TFSequence\n",
      "  File \"C:\\Users\\hp\\anaconda3\\envs\\tensorflow\\lib\\site-packages\\tensorflow\\keras\\__init__.py\", line 19, in <module>\n",
      "    from . import datasets\n",
      "  File \"C:\\Users\\hp\\anaconda3\\envs\\tensorflow\\lib\\site-packages\\tensorflow\\keras\\datasets\\__init__.py\", line 14, in <module>\n",
      "    from . import imdb\n",
      "  File \"C:\\Users\\hp\\anaconda3\\envs\\tensorflow\\lib\\site-packages\\tensorflow\\keras\\datasets\\imdb\\__init__.py\", line 10, in <module>\n",
      "    from tensorflow.python.keras.datasets.imdb import get_word_index\n",
      "  File \"C:\\Users\\hp\\anaconda3\\envs\\tensorflow\\lib\\site-packages\\tensorflow\\python\\keras\\datasets\\imdb.py\", line 21, in <module>\n",
      "    from tensorflow.python.keras.preprocessing.sequence import _remove_long_seq\n",
      "  File \"C:\\Users\\hp\\anaconda3\\envs\\tensorflow\\lib\\site-packages\\tensorflow\\python\\keras\\preprocessing\\__init__.py\", line 22, in <module>\n",
      "    from tensorflow.python.keras.preprocessing import image\n",
      "  File \"C:\\Users\\hp\\anaconda3\\envs\\tensorflow\\lib\\site-packages\\tensorflow\\python\\keras\\preprocessing\\image.py\", line 1122, in <module>\n",
      "    keras_export('keras.preprocessing.image.random_rotation')(random_rotation)\n",
      "  File \"C:\\Users\\hp\\anaconda3\\envs\\tensorflow\\lib\\site-packages\\tensorflow\\python\\util\\tf_export.py\", line 336, in __call__\n",
      "    delattr(undecorated_f, api_names_attr)\n",
      "  File \"C:\\Users\\hp\\anaconda3\\envs\\tensorflow\\lib\\site-packages\\tensorflow\\python\\util\\tf_export.py\", line 351, in set_attr\n",
      "    # __dict__ instead of using hasattr to verify that subclasses have\n",
      "tensorflow.python.util.tf_export.SymbolAlreadyExposedError: Symbol random_rotation is already exposed as ('keras.preprocessing.image.random_rotation',).\n",
      "\n",
      "During handling of the above exception, another exception occurred:\n",
      "\n",
      "Traceback (most recent call last):\n",
      "  File \"C:\\Users\\hp\\anaconda3\\envs\\tensorflow\\lib\\site-packages\\IPython\\core\\interactiveshell.py\", line 1993, in showtraceback\n",
      "    stb = self.InteractiveTB.structured_traceback(\n",
      "  File \"C:\\Users\\hp\\anaconda3\\envs\\tensorflow\\lib\\site-packages\\IPython\\core\\ultratb.py\", line 1118, in structured_traceback\n",
      "    return FormattedTB.structured_traceback(\n",
      "  File \"C:\\Users\\hp\\anaconda3\\envs\\tensorflow\\lib\\site-packages\\IPython\\core\\ultratb.py\", line 1012, in structured_traceback\n",
      "    return VerboseTB.structured_traceback(\n",
      "  File \"C:\\Users\\hp\\anaconda3\\envs\\tensorflow\\lib\\site-packages\\IPython\\core\\ultratb.py\", line 865, in structured_traceback\n",
      "    formatted_exception = self.format_exception_as_a_whole(etype, evalue, etb, number_of_lines_of_context,\n",
      "  File \"C:\\Users\\hp\\anaconda3\\envs\\tensorflow\\lib\\site-packages\\IPython\\core\\ultratb.py\", line 818, in format_exception_as_a_whole\n",
      "    frames.append(self.format_record(r))\n",
      "  File \"C:\\Users\\hp\\anaconda3\\envs\\tensorflow\\lib\\site-packages\\IPython\\core\\ultratb.py\", line 736, in format_record\n",
      "    result += ''.join(_format_traceback_lines(frame_info.lines, Colors, self.has_colors, lvals))\n",
      "  File \"C:\\Users\\hp\\anaconda3\\envs\\tensorflow\\lib\\site-packages\\stack_data\\utils.py\", line 145, in cached_property_wrapper\n",
      "    value = obj.__dict__[self.func.__name__] = self.func(obj)\n",
      "  File \"C:\\Users\\hp\\anaconda3\\envs\\tensorflow\\lib\\site-packages\\stack_data\\core.py\", line 698, in lines\n",
      "    pieces = self.included_pieces\n",
      "  File \"C:\\Users\\hp\\anaconda3\\envs\\tensorflow\\lib\\site-packages\\stack_data\\utils.py\", line 145, in cached_property_wrapper\n",
      "    value = obj.__dict__[self.func.__name__] = self.func(obj)\n",
      "  File \"C:\\Users\\hp\\anaconda3\\envs\\tensorflow\\lib\\site-packages\\stack_data\\core.py\", line 649, in included_pieces\n",
      "    pos = scope_pieces.index(self.executing_piece)\n",
      "  File \"C:\\Users\\hp\\anaconda3\\envs\\tensorflow\\lib\\site-packages\\stack_data\\utils.py\", line 145, in cached_property_wrapper\n",
      "    value = obj.__dict__[self.func.__name__] = self.func(obj)\n",
      "  File \"C:\\Users\\hp\\anaconda3\\envs\\tensorflow\\lib\\site-packages\\stack_data\\core.py\", line 628, in executing_piece\n",
      "    return only(\n",
      "  File \"C:\\Users\\hp\\anaconda3\\envs\\tensorflow\\lib\\site-packages\\executing\\executing.py\", line 164, in only\n",
      "    raise NotOneValueFound('Expected one value, found 0')\n",
      "executing.executing.NotOneValueFound: Expected one value, found 0\n"
     ]
    }
   ],
   "source": [
    "IMAGE_SIZE=224\n",
    "BATCH_SIZE=64\n",
    "\n",
    "train_datagen=tf.keras.preprocessing.image.ImageDataGenerator(\n",
    "    rescale=1./255,\n",
    "    shear_range=0.2,\n",
    "    zoom_range=0.2,\n",
    "    horizontal_flip=True,\n",
    "    vertical_flip=True,\n",
    "    validation_split=0.1\n",
    ")\n",
    "\n",
    "test_datagen=tf.keras.preprocessing.image.ImageDataGenerator(\n",
    "    rescale=1./255,\n",
    "    validation_split=0.1\n",
    ")\n",
    "train_datagen=train_datagen.flow_from_directory(\n",
    "    base_dir,\n",
    "    target_size=(IMAGE_SIZE,IMAGE_SIZE),\n",
    "    batch_size=BATCH_SIZE,\n",
    "    subset='training'\n",
    ")\n",
    "test_datagen=test_datagen.flow_from_directory(\n",
    "    base_dir,\n",
    "    target_size=(IMAGE_SIZE,IMAGE_SIZE),\n",
    "    batch_size=BATCH_SIZE,\n",
    "    subset='validation'\n",
    ")"
   ]
  },
  {
   "cell_type": "code",
   "execution_count": 6,
   "id": "c8f04af7",
   "metadata": {},
   "outputs": [],
   "source": [
    "IMAGE_SIZE=224\n",
    "BATCH_SIZE=64\n",
    "\n",
    "train_datagen=tf.keras.preprocessing.image.ImageDataGenerator(\n",
    "    rescale=1./255,\n",
    "    shear_range=0.2,\n",
    "    zoom_range=0.2,\n",
    "    horizontal_flip=True,\n",
    "    vertical_flip=True,\n",
    "    validation_split=0.1\n",
    ")"
   ]
  },
  {
   "cell_type": "code",
   "execution_count": 7,
   "id": "dc5c65bb",
   "metadata": {},
   "outputs": [
    {
     "name": "stdout",
     "output_type": "stream",
     "text": [
      "Unexpected exception formatting exception. Falling back to standard exception\n"
     ]
    },
    {
     "name": "stderr",
     "output_type": "stream",
     "text": [
      "Traceback (most recent call last):\n",
      "  File \"C:\\Users\\hp\\anaconda3\\envs\\tensorflow\\lib\\site-packages\\IPython\\core\\interactiveshell.py\", line 3398, in run_code\n",
      "    exec(code_obj, self.user_global_ns, self.user_ns)\n",
      "  File \"C:\\Users\\hp\\AppData\\Local\\Temp\\ipykernel_13080\\2581506346.py\", line 5, in <cell line: 5>\n",
      "    train_datagen=train_datagen.flow_from_directory(\n",
      "  File \"C:\\Users\\hp\\anaconda3\\envs\\tensorflow\\lib\\site-packages\\keras\\preprocessing\\image.py\", line 976, in flow_from_directory\n",
      "  File \"C:\\Users\\hp\\anaconda3\\envs\\tensorflow\\lib\\site-packages\\keras_preprocessing\\image\\directory_iterator.py\", line 69, in __new__\n",
      "    from tensorflow.keras.utils import Sequence as TFSequence\n",
      "  File \"C:\\Users\\hp\\anaconda3\\envs\\tensorflow\\lib\\site-packages\\tensorflow\\keras\\__init__.py\", line 19, in <module>\n",
      "    from . import datasets\n",
      "  File \"C:\\Users\\hp\\anaconda3\\envs\\tensorflow\\lib\\site-packages\\tensorflow\\keras\\datasets\\__init__.py\", line 14, in <module>\n",
      "    from . import imdb\n",
      "  File \"C:\\Users\\hp\\anaconda3\\envs\\tensorflow\\lib\\site-packages\\tensorflow\\keras\\datasets\\imdb\\__init__.py\", line 10, in <module>\n",
      "    from tensorflow.python.keras.datasets.imdb import get_word_index\n",
      "  File \"C:\\Users\\hp\\anaconda3\\envs\\tensorflow\\lib\\site-packages\\tensorflow\\python\\keras\\datasets\\imdb.py\", line 21, in <module>\n",
      "    from tensorflow.python.keras.preprocessing.sequence import _remove_long_seq\n",
      "  File \"C:\\Users\\hp\\anaconda3\\envs\\tensorflow\\lib\\site-packages\\tensorflow\\python\\keras\\preprocessing\\__init__.py\", line 22, in <module>\n",
      "    from tensorflow.python.keras.preprocessing import image\n",
      "  File \"C:\\Users\\hp\\anaconda3\\envs\\tensorflow\\lib\\site-packages\\tensorflow\\python\\keras\\preprocessing\\image.py\", line 1122, in <module>\n",
      "    keras_export('keras.preprocessing.image.random_rotation')(random_rotation)\n",
      "  File \"C:\\Users\\hp\\anaconda3\\envs\\tensorflow\\lib\\site-packages\\tensorflow\\python\\util\\tf_export.py\", line 336, in __call__\n",
      "    delattr(undecorated_f, api_names_attr)\n",
      "  File \"C:\\Users\\hp\\anaconda3\\envs\\tensorflow\\lib\\site-packages\\tensorflow\\python\\util\\tf_export.py\", line 351, in set_attr\n",
      "    # __dict__ instead of using hasattr to verify that subclasses have\n",
      "tensorflow.python.util.tf_export.SymbolAlreadyExposedError: Symbol random_rotation is already exposed as ('keras.preprocessing.image.random_rotation',).\n",
      "\n",
      "During handling of the above exception, another exception occurred:\n",
      "\n",
      "Traceback (most recent call last):\n",
      "  File \"C:\\Users\\hp\\anaconda3\\envs\\tensorflow\\lib\\site-packages\\IPython\\core\\interactiveshell.py\", line 1993, in showtraceback\n",
      "    stb = self.InteractiveTB.structured_traceback(\n",
      "  File \"C:\\Users\\hp\\anaconda3\\envs\\tensorflow\\lib\\site-packages\\IPython\\core\\ultratb.py\", line 1118, in structured_traceback\n",
      "    return FormattedTB.structured_traceback(\n",
      "  File \"C:\\Users\\hp\\anaconda3\\envs\\tensorflow\\lib\\site-packages\\IPython\\core\\ultratb.py\", line 1012, in structured_traceback\n",
      "    return VerboseTB.structured_traceback(\n",
      "  File \"C:\\Users\\hp\\anaconda3\\envs\\tensorflow\\lib\\site-packages\\IPython\\core\\ultratb.py\", line 865, in structured_traceback\n",
      "    formatted_exception = self.format_exception_as_a_whole(etype, evalue, etb, number_of_lines_of_context,\n",
      "  File \"C:\\Users\\hp\\anaconda3\\envs\\tensorflow\\lib\\site-packages\\IPython\\core\\ultratb.py\", line 818, in format_exception_as_a_whole\n",
      "    frames.append(self.format_record(r))\n",
      "  File \"C:\\Users\\hp\\anaconda3\\envs\\tensorflow\\lib\\site-packages\\IPython\\core\\ultratb.py\", line 736, in format_record\n",
      "    result += ''.join(_format_traceback_lines(frame_info.lines, Colors, self.has_colors, lvals))\n",
      "  File \"C:\\Users\\hp\\anaconda3\\envs\\tensorflow\\lib\\site-packages\\stack_data\\utils.py\", line 145, in cached_property_wrapper\n",
      "    value = obj.__dict__[self.func.__name__] = self.func(obj)\n",
      "  File \"C:\\Users\\hp\\anaconda3\\envs\\tensorflow\\lib\\site-packages\\stack_data\\core.py\", line 698, in lines\n",
      "    pieces = self.included_pieces\n",
      "  File \"C:\\Users\\hp\\anaconda3\\envs\\tensorflow\\lib\\site-packages\\stack_data\\utils.py\", line 145, in cached_property_wrapper\n",
      "    value = obj.__dict__[self.func.__name__] = self.func(obj)\n",
      "  File \"C:\\Users\\hp\\anaconda3\\envs\\tensorflow\\lib\\site-packages\\stack_data\\core.py\", line 649, in included_pieces\n",
      "    pos = scope_pieces.index(self.executing_piece)\n",
      "  File \"C:\\Users\\hp\\anaconda3\\envs\\tensorflow\\lib\\site-packages\\stack_data\\utils.py\", line 145, in cached_property_wrapper\n",
      "    value = obj.__dict__[self.func.__name__] = self.func(obj)\n",
      "  File \"C:\\Users\\hp\\anaconda3\\envs\\tensorflow\\lib\\site-packages\\stack_data\\core.py\", line 628, in executing_piece\n",
      "    return only(\n",
      "  File \"C:\\Users\\hp\\anaconda3\\envs\\tensorflow\\lib\\site-packages\\executing\\executing.py\", line 164, in only\n",
      "    raise NotOneValueFound('Expected one value, found 0')\n",
      "executing.executing.NotOneValueFound: Expected one value, found 0\n"
     ]
    }
   ],
   "source": [
    "test_datagen=tf.keras.preprocessing.image.ImageDataGenerator(\n",
    "    rescale=1./255,\n",
    "    validation_split=0.1\n",
    ")\n",
    "train_datagen=train_datagen.flow_from_directory(\n",
    "    base_dir,\n",
    "    target_size=(IMAGE_SIZE,IMAGE_SIZE),\n",
    "    batch_size=BATCH_SIZE,\n",
    "    subset='training'\n",
    ")\n",
    "test_datagen=test_datagen.flow_from_directory(\n",
    "    base_dir,\n",
    "    target_size=(IMAGE_SIZE,IMAGE_SIZE),\n",
    "    batch_size=BATCH_SIZE,\n",
    "    subset='validation'\n",
    ")"
   ]
  },
  {
   "cell_type": "code",
   "execution_count": 8,
   "id": "1fba76d5",
   "metadata": {},
   "outputs": [],
   "source": [
    "test_datagen=tf.keras.preprocessing.image.ImageDataGenerator(\n",
    "    rescale=1./255,\n",
    "    validation_split=0.1\n",
    ")"
   ]
  },
  {
   "cell_type": "code",
   "execution_count": 9,
   "id": "637a7a32",
   "metadata": {},
   "outputs": [
    {
     "name": "stdout",
     "output_type": "stream",
     "text": [
      "Unexpected exception formatting exception. Falling back to standard exception\n"
     ]
    },
    {
     "name": "stderr",
     "output_type": "stream",
     "text": [
      "Traceback (most recent call last):\n",
      "  File \"C:\\Users\\hp\\anaconda3\\envs\\tensorflow\\lib\\site-packages\\IPython\\core\\interactiveshell.py\", line 3398, in run_code\n",
      "    exec(code_obj, self.user_global_ns, self.user_ns)\n",
      "  File \"C:\\Users\\hp\\AppData\\Local\\Temp\\ipykernel_13080\\3758183690.py\", line 1, in <cell line: 1>\n",
      "    train_datagen=train_datagen.flow_from_directory(\n",
      "  File \"C:\\Users\\hp\\anaconda3\\envs\\tensorflow\\lib\\site-packages\\keras\\preprocessing\\image.py\", line 976, in flow_from_directory\n",
      "  File \"C:\\Users\\hp\\anaconda3\\envs\\tensorflow\\lib\\site-packages\\keras_preprocessing\\image\\directory_iterator.py\", line 69, in __new__\n",
      "    from tensorflow.keras.utils import Sequence as TFSequence\n",
      "  File \"C:\\Users\\hp\\anaconda3\\envs\\tensorflow\\lib\\site-packages\\tensorflow\\keras\\__init__.py\", line 19, in <module>\n",
      "    from . import datasets\n",
      "  File \"C:\\Users\\hp\\anaconda3\\envs\\tensorflow\\lib\\site-packages\\tensorflow\\keras\\datasets\\__init__.py\", line 14, in <module>\n",
      "    from . import imdb\n",
      "  File \"C:\\Users\\hp\\anaconda3\\envs\\tensorflow\\lib\\site-packages\\tensorflow\\keras\\datasets\\imdb\\__init__.py\", line 10, in <module>\n",
      "    from tensorflow.python.keras.datasets.imdb import get_word_index\n",
      "  File \"C:\\Users\\hp\\anaconda3\\envs\\tensorflow\\lib\\site-packages\\tensorflow\\python\\keras\\datasets\\imdb.py\", line 21, in <module>\n",
      "    from tensorflow.python.keras.preprocessing.sequence import _remove_long_seq\n",
      "  File \"C:\\Users\\hp\\anaconda3\\envs\\tensorflow\\lib\\site-packages\\tensorflow\\python\\keras\\preprocessing\\__init__.py\", line 22, in <module>\n",
      "    from tensorflow.python.keras.preprocessing import image\n",
      "  File \"C:\\Users\\hp\\anaconda3\\envs\\tensorflow\\lib\\site-packages\\tensorflow\\python\\keras\\preprocessing\\image.py\", line 1122, in <module>\n",
      "    keras_export('keras.preprocessing.image.random_rotation')(random_rotation)\n",
      "  File \"C:\\Users\\hp\\anaconda3\\envs\\tensorflow\\lib\\site-packages\\tensorflow\\python\\util\\tf_export.py\", line 336, in __call__\n",
      "    delattr(undecorated_f, api_names_attr)\n",
      "  File \"C:\\Users\\hp\\anaconda3\\envs\\tensorflow\\lib\\site-packages\\tensorflow\\python\\util\\tf_export.py\", line 351, in set_attr\n",
      "    # __dict__ instead of using hasattr to verify that subclasses have\n",
      "tensorflow.python.util.tf_export.SymbolAlreadyExposedError: Symbol random_rotation is already exposed as ('keras.preprocessing.image.random_rotation',).\n",
      "\n",
      "During handling of the above exception, another exception occurred:\n",
      "\n",
      "Traceback (most recent call last):\n",
      "  File \"C:\\Users\\hp\\anaconda3\\envs\\tensorflow\\lib\\site-packages\\IPython\\core\\interactiveshell.py\", line 1993, in showtraceback\n",
      "    stb = self.InteractiveTB.structured_traceback(\n",
      "  File \"C:\\Users\\hp\\anaconda3\\envs\\tensorflow\\lib\\site-packages\\IPython\\core\\ultratb.py\", line 1118, in structured_traceback\n",
      "    return FormattedTB.structured_traceback(\n",
      "  File \"C:\\Users\\hp\\anaconda3\\envs\\tensorflow\\lib\\site-packages\\IPython\\core\\ultratb.py\", line 1012, in structured_traceback\n",
      "    return VerboseTB.structured_traceback(\n",
      "  File \"C:\\Users\\hp\\anaconda3\\envs\\tensorflow\\lib\\site-packages\\IPython\\core\\ultratb.py\", line 865, in structured_traceback\n",
      "    formatted_exception = self.format_exception_as_a_whole(etype, evalue, etb, number_of_lines_of_context,\n",
      "  File \"C:\\Users\\hp\\anaconda3\\envs\\tensorflow\\lib\\site-packages\\IPython\\core\\ultratb.py\", line 818, in format_exception_as_a_whole\n",
      "    frames.append(self.format_record(r))\n",
      "  File \"C:\\Users\\hp\\anaconda3\\envs\\tensorflow\\lib\\site-packages\\IPython\\core\\ultratb.py\", line 736, in format_record\n",
      "    result += ''.join(_format_traceback_lines(frame_info.lines, Colors, self.has_colors, lvals))\n",
      "  File \"C:\\Users\\hp\\anaconda3\\envs\\tensorflow\\lib\\site-packages\\stack_data\\utils.py\", line 145, in cached_property_wrapper\n",
      "    value = obj.__dict__[self.func.__name__] = self.func(obj)\n",
      "  File \"C:\\Users\\hp\\anaconda3\\envs\\tensorflow\\lib\\site-packages\\stack_data\\core.py\", line 698, in lines\n",
      "    pieces = self.included_pieces\n",
      "  File \"C:\\Users\\hp\\anaconda3\\envs\\tensorflow\\lib\\site-packages\\stack_data\\utils.py\", line 145, in cached_property_wrapper\n",
      "    value = obj.__dict__[self.func.__name__] = self.func(obj)\n",
      "  File \"C:\\Users\\hp\\anaconda3\\envs\\tensorflow\\lib\\site-packages\\stack_data\\core.py\", line 649, in included_pieces\n",
      "    pos = scope_pieces.index(self.executing_piece)\n",
      "  File \"C:\\Users\\hp\\anaconda3\\envs\\tensorflow\\lib\\site-packages\\stack_data\\utils.py\", line 145, in cached_property_wrapper\n",
      "    value = obj.__dict__[self.func.__name__] = self.func(obj)\n",
      "  File \"C:\\Users\\hp\\anaconda3\\envs\\tensorflow\\lib\\site-packages\\stack_data\\core.py\", line 628, in executing_piece\n",
      "    return only(\n",
      "  File \"C:\\Users\\hp\\anaconda3\\envs\\tensorflow\\lib\\site-packages\\executing\\executing.py\", line 164, in only\n",
      "    raise NotOneValueFound('Expected one value, found 0')\n",
      "executing.executing.NotOneValueFound: Expected one value, found 0\n"
     ]
    }
   ],
   "source": [
    "train_datagen=train_datagen.flow_from_directory(\n",
    "    base_dir,\n",
    "    target_size=(IMAGE_SIZE,IMAGE_SIZE),\n",
    "    batch_size=BATCH_SIZE,\n",
    "    subset='training'\n",
    ")"
   ]
  },
  {
   "cell_type": "code",
   "execution_count": null,
   "id": "914b312b",
   "metadata": {},
   "outputs": [],
   "source": []
  }
 ],
 "metadata": {
  "kernelspec": {
   "display_name": "Python 3 (ipykernel)",
   "language": "python",
   "name": "python3"
  },
  "language_info": {
   "codemirror_mode": {
    "name": "ipython",
    "version": 3
   },
   "file_extension": ".py",
   "mimetype": "text/x-python",
   "name": "python",
   "nbconvert_exporter": "python",
   "pygments_lexer": "ipython3",
   "version": "3.9.12"
  }
 },
 "nbformat": 4,
 "nbformat_minor": 5
}
